Workbook

Sheet Revenue
F2: Block 1 (OLD) | G2: Block 2 (OLD) | H2: Block 1 | I2: Block 2a | J2: Block 2b | K2: Block 3 | L2: Block 4 (1) | M2: Block 5 (6W) | N2: Block 6 (6M) | O2: Block 7 (6E) | P2: Block 8 | Q2: Block 9 | R2: Block 10 | S2: Block 11 | T2: Block 12 | U2: Block 13W | V2: Block 14 | W2: Block 15 | X2: Block 16L | Y2: Block 17 | Z2: Block 18 | AA2: Block 19
F3: Atwood | G3: Washington | H3: Clementines | I3: Tangos | J3: Clementines | K3: Washingtons | L3: Valencia | M3: Valencia | N3: Valencia | O3: Valencia | P3: Late Lane | Q3: Cara Caras | R3: Powells | S3: Tangos | T3: Lemons | U3: Washingtons | V3: Washingtons | W3: Grapefruit | X3: Lemons | Y3: Tangos | Z3: Washingtons | AA3: Cara Caras | AB3: Total | AC3: Other
E4: Year Planted | H4: 2017 | I4: 2017 | J4: 2014 | K4: 1964 | L4: 1964 | M4: 1989 | N4: 1998 | O4: 1998 | P4: 1998 | Q4: 2013 | R4: 2013 | S4: 2018 | T4: 2013 | U4: ??? | V4: 2020 | W4: 2020 | X4: 2020 | Y4: 2020 | Z4: 2020 | AA4: 2020
E5: Planted Acres | F5: 20 | G5: 9.5 | H5: 20 | I5: 10 | J5: 10 | K5: 20 | L5: 20 | M5: 5 | N5: 8 | O5: 24 | P5: 20 | Q5: 20 | R5: 20 | S5: 17.5 | T5: 18 | U5: 5.5 | V5: 10.39 | W5: 9.57 | X5: 20 | Y5: 10.68 | Z5: 39.67 | AA5: 11.54 | AB5: Citrus | AC5: Revenue | AD5: Olives
C8: 2012 | E8: Total Field Boxes | F8: =3200+4672+192 -> 8064 | G8: 3632 | K8: =2400+3584+2776 -> 8760 | L8: 11888 | M8: 3328 | N8: =445*16 -> 7120 | O8: =1224*16 -> 19584 | P8: =4816+6672 -> 11488 | AB8: =SUM(F8:T8) -> 73864
E9: Field Boxes Per Acre | F9: =+F8/F5 -> 403.2 | G9: =+G8/G5 -> 382.31579 | K9: =+K8/K5 -> 438 | L9: =+L8/L5 -> 594.4 | M9: =+M8/M5 -> 665.6 | N9: =+N8/N5 -> 890 | O9: =+O8/O5 -> 816 | P9: =+P8/P5 -> 574.4
E10: Total Bins (Tons) | F10: =+F8/16 -> 504 | G10: =+G8/16 -> 227 | K10: =+K8/16 -> 547.5 | L10: =+L8/16 -> 743 | M10: =+M8/16 -> 208 | N10: =+N8/16 -> 445 | O10: =+O8/16 -> 1224 | P10: =+P8/16 -> 718 | AB10: =SUM(F10:T10) -> 4616.5 | AD10: 20.05
E11: Bins per Acre | F11: =+F10/F5 -> 25.2 | G11: =+G10/G5 -> 23.894737 | K11: =+K10/K5 -> 27.375 | L11: =+L10/L5 -> 37.15 | M11: =+M10/M5 -> 41.6 | N11: =+N10/N5 -> 55.625 | O11: =+O10/O5 -> 51 | P11: =+P10/P5 -> 35.9
E13: $ / Bin | F13: 174.67891 | G13: 128.46753 | K13: 97.465845 | L13: 77.481157 | M13: 78.570144 | N13: 71.913416 | O13: 57.286814 | P13: 117.72584 | AB13: =AB15/AB10 -> 93.387116
E15: Total Revenue | F15: =+F13*F10 -> 88038.17 | G15: =+G13*G10 -> 29162.13 | K15: =+K13*K10 -> 53362.55 | L15: =+L13*L10 -> 57568.5 | M15: =+M13*M10 -> 16342.59 | N15: =+N13*N10 -> 32001.47 | O15: =+O13*O10 -> 70119.06 | P15: =+P13*P10 -> 84527.15 | AB15: =SUM(F15:T15) -> 431121.62 | AD15: 10000 | AE15: =SUM(AB15:AD15) -> 441121.62
C19: 2013 | E19: Total Field Boxes | F19: =+F21*16 -> 4912 | G19: =+G21*16 -> 2112 | K19: =+K21*16 -> 5192 | L19: =+L21*16 -> 6528 | M19: =+M21*16 -> 2400 | N19: =+N21*16 -> 3552 | O19: =+O21*16 -> 13200 | P19: =+P21*16 -> 5408 | AB19: =SUM(F19:T19) -> 43304
E20: Field Boxes Per Acre | F20: =+F19/F5 -> 245.6 | G20: =+G19/G5 -> 222.31579 | K20: =+K19/K5 -> 259.6 | L20: =+L19/L5 -> 326.4 | M20: =+M19/M5 -> 480 | N20: =+N19/N5 -> 444 | O20: =+O19/O5 -> 550 | P20: =+P19/P5 -> 270.4
E21: Total Bins (Tons) | F21: =205+102 -> 307 | G21: 132 | K21: 324.5 | L21: 408 | M21: 150 | N21: 222 | O21: 825 | P21: 338 | AB21: =SUM(F21:T21) -> 2706.5 | AD21: 106.26
E22: Bins per Acre | F22: =+F21/F5 -> 15.35 | G22: =+G21/G5 -> 13.894737 | K22: =+K21/K5 -> 16.225 | L22: =+L21/L5 -> 20.4 | M22: =+M21/M5 -> 30 | N22: =+N21/N5 -> 27.75 | O22: =+O21/O5 -> 34.375 | P22: =+P21/P5 -> 16.9
E24: $ / Bin | F24: =F26/F21 -> 133.93293 | G24: =G26/G21 -> 139.41614 | K24: =K26/K21 -> 150.34284 | L24: =L26/L21 -> 131.76679 | M24: =M26/M21 -> 131.03327 | N24: =N26/N21 -> 118.94333 | O24: =O26/O21 -> 120.40113 | P24: =P26/P21 -> 224.0103 | AB24: =AB26/AB21 -> 141.57556
E26: Checks Received | F26: ='2013 - Checks'!E3+'2013 - Checks'!E4+'2013 - Checks'!E10+'2013 - Checks'!E11+'2013 - Checks'!E19+'2013 - Checks'!E22 -> 41117.41 | G26: ='2013 - Checks'!E5+'2013 - Checks'!E12+'2013 - Checks'!E23 -> 18402.93 | K26: =+'2013 - Checks'!E6+'2013 - Checks'!E7+'2013 - Checks'!E13+'2013 - Checks'!E24+'2013 - Checks'!E27 -> 48786.25 | L26: ='2013 - Checks'!E39+'2013 - Checks'!E33 -> 53760.85 | M26: ='2013 - Checks'!E40+'2013 - Checks'!E34 -> 19654.99 | N26: ='2013 - Checks'!E41+'2013 - Checks'!E35 -> 26405.42 | O26: ='2013 - Checks'!E42+'2013 - Checks'!E36 -> 99330.93 | P26: =+'2013 - Checks'!E16+'2013 - Checks'!E31 -> 75715.48 | AB26: =SUM(F26:T26) -> 383174.26 | AC26: =(11401.02-10000)+21169.6+6727 -> 29297.62 | AD26: ='2013 - Checks'!E46 -> 48069.6 | AE26: =SUM(AB26:AD26) -> 460541.48
C30: 2014 | E30: Total Field Boxes | F30: =+F32*16 -> 5600 | G30: =+G32*16 -> 3328 | K30: =+K32*16 -> 9600 | L30: =+L32*16 -> 13568 | M30: =+M32*16 -> 4032 | N30: =+N32*16 -> 7200 | O30: =+O32*16 -> 17452 | P30: =+P32*16 -> 8224 | AB30: =SUM(F30:T30) -> 69004
E31: Field Boxes Per Acre | F31: =+F30/F5 -> 280 | G31: =+G30/G5 -> 350.31579 | K31: =+K30/K5 -> 480 | L31: =+L30/L5 -> 678.4 | M31: =+M30/M5 -> 806.4 | N31: =+N30/N5 -> 900 | O31: =+O30/O5 -> 727.16667 | P31: =+P30/P5 -> 411.2
E32: Total Bins (Tons) | F32: 350 | G32: 208 | K32: 600 | L32: 848 | M32: 252 | N32: 450 | O32: 1090.75 | P32: 514 | AB32: =SUM(F32:T32) -> 4312.75 | AD32: 16.465
E33: Bins per Acre | F33: =+F32/29.5 -> 11.864407 | G33: =+G32/29.5 -> 7.0508475 | K33: =+K32/K5 -> 30 | L33: =+L32/L5 -> 42.4 | M33: =+M32/M5 -> 50.4 | N33: =+N32/N5 -> 56.25 | O33: =+O32/O5 -> 45.447917 | P33: =+P32/P5 -> 25.7
E35: $ / Bin | F35: =+F37/F32 -> 222.48129 | G35: =+G37/G32 -> 214.96644 | K35: =+K37/K32 -> 242.77287 | L35: =+L37/L32 -> 142.25303 | M35: =+M37/M32 -> 145.38258 | N35: =+N37/N32 -> 100.97938 | O35: =+O37/O32 -> 82.81532 | P35: =+P37/P32 -> 242.27613 | AB35: =AB37/AB32 -> 159.02003
E37: Estimated Revenue | F37: =SUM('2014 - Checks'!E8,'2014 - Checks'!E15,'2014 - Checks'!E26,'2014 - Checks'!E35,) -> 77868.45 | G37: =SUM('2014 - Checks'!E9,'2014 - Checks'!E16,'2014 - Checks'!E24,'2014 - Checks'!E36,) -> 44713.02 | K37: ='2014 - Checks'!E3+'2014 - Checks'!E19+'2014 - Checks'!E4+'2014 - Checks'!E7+'2014 - Checks'!E20+'2014 - Checks'!E10+'2014 - Checks'!E25+'2014 - Checks'!E27 -> 145663.72 | L37: ='2014 - Checks'!E30+'2014 - Checks'!E41 -> 120630.57 | M37: ='2014 - Checks'!E31+'2014 - Checks'!E42 -> 36636.41 | N37: ='2014 - Checks'!E43 -> 45440.72 | O37: ='2014 - Checks'!E32+'2014 - Checks'!E44 -> 90330.81 | P37: =+'2014 - Checks'!E13+'2014 - Checks'!E39 -> 124529.93 | AB37: =SUM(F37:T37) -> 685813.63 | AC37: =SUM(#REF!) -> #REF! | AD37: 6692.65 | AE37: =SUM(AB37:AD37) -> #REF!
F40: c
C41: 2015 | E41: Total Field Boxes | F41: =+F43*16 -> 4288 | G41: =+G43*16 -> 2400 | K41: =+K43*16 -> 7760 | L41: =+L43*16 -> 10032 | M41: =+M43*16 -> 1840 | N41: =+N43*16 -> 3232 | O41: =+O43*16 -> 13504 | P41: =+P43*16 -> 9344 | T41: =+T43*16 -> 380 | AB41: =SUM(F41:T41) -> 52780
E42: Field Boxes Per Acre | F42: =+F41/F5 -> 214.4 | G42: =+G41/G5 -> 252.63158 | K42: =+K41/K5 -> 388 | L42: =+L41/L5 -> 501.6 | M42: =+M41/M5 -> 368 | N42: =+N41/N5 -> 404 | O42: =+O41/O5 -> 562.66667 | P42: =+P41/P5 -> 467.2 | T42: =+T41/T5 -> 21.111111
E43: Total Bins (Tons) | F43: 268 | G43: 150 | K43: 485 | L43: =294+100+233 -> 627 | M43: 115 | N43: 202 | O43: 844 | P43: 584 | T43: =23.75 -> 23.75 | AB43: =SUM(F43:T43) -> 3298.75 | AD43: 145.245
E44: Bins per Acre | F44: =+F43/F5 -> 13.4 | G44: =+G43/G5 -> 15.789474 | K44: =+K43/K5 -> 24.25 | L44: =+L43/L5 -> 31.35 | M44: =+M43/M5 -> 23 | N44: =+N43/N5 -> 25.25 | O44: =+O43/O5 -> 35.166667 | P44: =+P43/P5 -> 29.2 | T44: =+T43/T5 -> 1.3194444
E46: $ / Bin | F46: =+F48/F43 -> 157.50638 | G46: =+G48/G43 -> 161.72293 | K46: =+K48/K43 -> 140.95338 | L46: =+L48/L43 -> 132.79362 | M46: =+M48/M43 -> 110.22548 | N46: =+N48/N43 -> 133.8896 | O46: =+O48/O43 -> 126.08985 | P46: =+P48/P43 -> 230.92279 | T46: =+T48/T43 -> 219.70737 | AB46: =AB48/AB43 -> 152.8799
E48: Estimated Revenue | F48: =+'2015 - Checks'!E12+'2015 - Checks'!E2 -> 42211.71 | G48: =+'2015 - Checks'!E3+'2015 - Checks'!E4+'2015 - Checks'!E13+'2015 - Checks'!E16 -> 24258.44 | K48: =+'2015 - Checks'!E17+'2015 - Checks'!E5 -> 68362.39 | L48: ='2015 - Checks'!E27 -> 83261.6 | M48: ='2015 - Checks'!E20+'2015 - Checks'!E28 -> 12675.93 | N48: =+'2015 - Checks'!E21+'2015 - Checks'!E29 -> 27045.7 | O48: =+'2015 - Checks'!E22+'2015 - Checks'!E30 -> 106419.83 | P48: =+'2015 - Checks'!E8+'2015 - Checks'!E25 -> 134858.91 | T48: ='2015 - Checks'!E10 -> 5218.05 | AB48: =SUM(F48:T48) -> 504312.56 | AD48: =71462.94+51963.17 -> 123426.11 | AE48: =SUM(AB48:AD48) -> 627738.67
C52: 2016 | E52: Total Field Boxes | F52: =+F54*16 -> 8512 | G52: =+G54*16 -> 4064 | K52: =+K54*16 -> 13088 | L52: =+L54*16 -> 14464 | M52: =+M54*16 -> 4800 | N52: =+N54*16 -> 8288 | O52: =+O54*16 -> 21664 | P52: =+P54*16 -> 12192 | Q52: 224 | T52: =+T54*16 -> 4528 | AB52: =SUM(F52:T52) -> 91824
E53: Field Boxes Per Acre | F53: =+F52/F5 -> 425.6 | G53: =+G52/G5 -> 427.78947 | K53: =+K52/K5 -> 654.4 | L53: =+L52/L5 -> 723.2 | M53: =+M52/M5 -> 960 | N53: =+N52/N5 -> 1036 | O53: =+O52/O5 -> 902.66667 | P53: =+P52/P5 -> 609.6 | Q53: =+Q52/Q5 -> 11.2 | T53: =+T52/T5 -> 251.55556
E54: Total Bins (Tons) | F54: =397+135 -> 532 | G54: =50+204 -> 254 | K54: 818 | L54: 904 | M54: 300 | N54: 518 | O54: 1354 | P54: 762 | Q54: 14 | T54: 283 | AB54: =SUM(F54:T54) -> 5739 | AD54: 8.8
E55: Bins per Acre | F55: =+F54/F5 -> 26.6 | G55: =+G54/G5 -> 26.736842 | K55: =+K54/K5 -> 40.9 | L55: =+L54/L5 -> 45.2 | M55: =+M54/M5 -> 60 | N55: =+N54/N5 -> 64.75 | O55: =+O54/O5 -> 56.416667 | P55: =+P54/P5 -> 38.1 | Q55: =+Q54/Q5 -> 0.7 | T55: =+T54/T5 -> 15.722222
E57: $ / Bin | F57: =+F59/F54 -> 142.35296 | G57: =+G59/G54 -> 50.541389 | K57: =+K59/K54 -> 62.688366 | L57: =+L59/L54 -> 100.31597 | M57: =+M59/M54 -> 86.459033 | N57: =+N59/N54 -> 85.335386 | O57: =+O59/O54 -> 75.788774 | P57: =+P59/P54 -> 88.878751 | Q57: =+Q59/Q54 -> 183.39929 | T57: =+T59/T54 -> 271.02565 | AB57: =AB59/AB54 -> 95.885504
E59: Estimated Revenue | F59: ='2016 - Checks'!C54 -> 75731.776 | G59: ='2016 - Checks'!C55 -> 12837.513 | K59: ='2016 - Checks'!C56 -> 51279.083 | L59: ='2016 - Checks'!C57 -> 90685.64 | M59: ='2016 - Checks'!C58 -> 25937.71 | N59: ='2016 - Checks'!C59 -> 44203.73 | O59: ='2016 - Checks'!C60 -> 102618 | P59: ='2016 - Checks'!C61 -> 67725.608 | Q59: ='2016 - Checks'!E22 -> 2567.59 | T59: ='2016 - Checks'!E18 -> 76700.26 | AB59: =SUM(F59:T59) -> 550286.91 | AD59: 10269.95 | AE59: =SUM(AB59:AD59) -> 560556.86 | AH59: Does not match quickbooks. Also, Blk 2 revenue does not match the final growers report
C63: 2017 | E63: Total Field Boxes | K63: =+K65*16 -> 11104 | L63: =+L65*16 -> 10472 | M63: =+M65*16 -> 2752 | N63: =+N65*16 -> 4288 | O63: =+O65*16 -> 15904 | P63: =+P65*16 -> 7776 | Q63: =+Q65*16 -> 1504 | R63: =+R65*16 -> 1312 | T63: =+T65*16 -> 4400 | AB63: =SUM(F63:T63) -> 59512
E64: Field Boxes Per Acre | K64: =+K63/K5 -> 555.2 | L64: =+L63/L5 -> 523.6 | M64: =+M63/M5 -> 550.4 | N64: =+N63/N5 -> 536 | O64: =+O63/O5 -> 662.66667 | P64: =+P63/P5 -> 388.8 | Q64: =+Q63/Q5 -> 75.2 | R64: =+R63/R5 -> 65.6 | T64: =+T63/T5 -> 244.44444
E65: Total Bins (Tons) | K65: 694 | L65: 654.5 | M65: 172 | N65: 268 | O65: 994 | P65: 486 | Q65: 94 | R65: 82 | T65: 275 | AB65: =SUM(F65:T65) -> 3719.5 | AD65: 25.131
E66: Bins per Acre | K66: =+K65/K5 -> 34.7 | L66: =+L65/L5 -> 32.725 | M66: =+M65/M5 -> 34.4 | N66: =+N65/N5 -> 33.5 | O66: =+O65/O5 -> 41.416667 | P66: =+P65/P5 -> 24.3 | Q66: =+Q65/Q5 -> 4.7 | R66: =+R65/R5 -> 4.1 | T66: =+T65/T5 -> 15.277778
E68: $ / Bin | K68: =K70/K65 -> 166.82767 | L68: =L70/L65 -> 243.79027 | M68: =M70/M65 -> 223.22791 | N68: =N70/N65 -> 204.77563 | O68: =O70/O65 -> 241.6324 | P68: =+P70/P65 -> 295.81012 | Q68: =+Q70/Q65 -> 135.19628 | R68: =+R70/R65 -> 132.42085 | T68: =+T70/T65 -> 260.52775 | AB68: 0
...

Sheet Conversion
A1: RMA Yield to Bins/Acre Converter
F2: Commodity | G2: PH CTN/Bin | H2: PH Lbs/Bin | I2: RMA Lb/CTN
A3: Commodity: | B3: Clementines | F3: Clementines | G3: 173.5 | H3: =G3*5 -> 867.5 | I3: 25
A4: RMA Yield (CTN/Acre): | B4: 864 | F4: Tangos | G4: 173.5 | H4: =G4*5 -> 867.5 | I4: 25
F5: Washington (Jireh) | G5: 23.2 | H5: =G5*40 -> 928 | I5: 38
A6: Yield (Bins/Acre): | B6: =IFERROR(IF(OR(B3="",B4=""),"",B4*VLOOKUP(B3,F3:I13,4,FALSE)/VLOOKUP(B3,F3:I13,3,FALSE)),"Invalid Commodity") -> 24.899135 | F6: Washingtons | G6: 23 | H6: =G6*40 -> 920 | I6: 38
F7: Valencia | G7: 23.2 | H7: =G7*40 -> 928 | I7: 38
A8: Formula: (RMA CTN/Acre) × (RMA Lb/CTN) ÷ (PH Lbs/Bin) | F8: Late Lane | G8: 23 | H8: =G8*40 -> 920 | I8: 38
F9: Cara Caras | G9: 23 | H9: =G9*40 -> 920 | I9: 38
A10: $/CTN to $/Bin Converter | F10: Powells | G10: 23 | H10: =G10*40 -> 920 | I10: 38
F11: Lemons | G11: 22 | H11: =G11*40 -> 880 | I11: 40
A12: Commodity: | B12: Lemons | F12: Grapefruit | G12: 23.2 | H12: =G12*35 -> 812 | I12: 32
A13: $/CTN (RMA): | B13: 11.05
A15: $/Bin: | B15: =IFERROR(IF(OR(B12="",B13=""),"",B13*VLOOKUP(B12,F3:I13,3,FALSE)/VLOOKUP(B12,F3:I13,4,FALSE)),"Invalid Commodity") -> 243.1
A17: Formula: ($/CTN) × (PH Lbs/Bin) ÷ (RMA Lb/CTN)
B22: =15.7/25 -> 0.628
B23: =B22*5 -> 3.14
B24: =B23*G3 -> 544.79
C26: ctn (5lb) | D26: 33139
C27: ctn (25lb) | D27: =D26/5 -> 6627.8
C28: bin | D28: 191
C29: ctn (25/lb)/bin | D29: =D27/D28 -> 34.700524
C30: $/CTN | D30: 15.7
C31: Total $ | D31: =D30*D27 -> 104056.46
C32: $/bin | D32: =D31/D28 -> 544.79822

Sheet 2026 Checks
B1: Check Date | C1: Block | D1: Amount | E1: Packhouse | F1: Comments | I1: Block | J1: 2025 Total Check Amount | K1: 2025 Bins | L1: 2025 $/Bin | M1: Final/Not Final | N1: Notes
B2: 46026 | C2: Block 12 | D2: 31250 | E2: Sun Pacific | F2: LEM-Blk12-ADV-OCT/NOV | I2: Block 1 | J2: =SUMIF($C$2:$C$50,I2,$D$2:$D$50) -> 78986.43 | K2: 566 | L2: =J2/K2 -> 139.552 | M2: Final
B3: 46026 | C3: Block 16L | D3: 16850 | E3: Sun Pacific | F3: LEM-Blk16L-ADV-OCT/NOV | I3: Block 2A | J3: =SUMIF($C$2:$C$50,I3,$D$2:$D$50) -> 39300 | L3: =J3/K3 -> #DIV/0!
B4: 46026 | C4: Block 1 | D4: 42050 | E4: Sun Pacific | F4: CLM-Blk1-ADV-OCT/NOV | I4: Block 2B | J4: =SUMIF($C$2:$C$50,I4,$D$2:$D$50) -> 66447.3 | K4: 428 | L4: =J4/K4 -> 155.2507 | M4: Final
B5: 46026 | C5: Block 2B | D5: 37000 | E5: Sun Pacific | F5: CLM-Blk2B-ADV-OCT/NOV | I5: Block 3 | J5: =SUMIF($C$2:$C$50,I5,$D$2:$D$50) -> 0 | L5: =J5/K5 -> #DIV/0!
B6: 46047 | C6: Block 1 | D6: 14100 | E6: Sun Pacific | F6: CLM-Blk1-ADV-DEC | I6: Block 4 | J6: =SUMIF($C$2:$C$50,I6,$D$2:$D$50) -> 0 | L6: =J6/K6 -> #DIV/0!
B7: 46047 | C7: Block 2B | D7: 13100 | E7: Sun Pacific | F7: CLM-Blk2B-ADV-DEC | I7: Block 5 | J7: =SUMIF($C$2:$C$50,I7,$D$2:$D$50) -> 0 | L7: =J7/K7 -> #DIV/0!
B8: 46083 | C8: Block 1 | D8: 9800 | E8: Sun Pacific | F8: CLM-Blk1-ADV-JAN | I8: Block 6 | J8: =SUMIF($C$2:$C$50,I8,$D$2:$D$50) -> 0 | L8: =J8/K8 -> #DIV/0!
B9: 46083 | C9: Block 11 | D9: 86150 | E9: Sun Pacific | F9: MUR-Blk11-ADV-JAN | I9: Block 7 | J9: =SUMIF($C$2:$C$50,I9,$D$2:$D$50) -> 0 | L9: =J9/K9 -> #DIV/0!
B10: 46083 | C10: Block 12 | D10: 1200 | E10: Sun Pacific | F10: LEM-Blk12-ADV-JAN | I10: Block 8 | J10: =SUMIF($C$2:$C$50,I10,$D$2:$D$50) -> 0 | L10: =J10/K10 -> #DIV/0!
B11: 46083 | C11: Block 16L | D11: 14250 | E11: Sun Pacific | F11: LEM-Blk16L-ADV-JAN | I11: Block 9 | J11: =SUMIF($C$2:$C$50,I11,$D$2:$D$50) -> 43500 | L11: =J11/K11 -> #DIV/0!
B12: 46083 | C12: Block 19C | D12: 10350 | E12: Sun Pacific | F12: CAR-Blk19C-ADV-JAN | I12: Block 10 | J12: =SUMIF($C$2:$C$50,I12,$D$2:$D$50) -> 0 | L12: =J12/K12 -> #DIV/0!
B13: 46083 | C13: Block 2A | D13: 39300 | E13: Sun Pacific | F13: MUR-Blk2A-ADV-JAN | I13: Block 11 | J13: =SUMIF($C$2:$C$50,I13,$D$2:$D$50) -> 86150 | L13: =J13/K13 -> #DIV/0!
B14: 46083 | C14: Block 2B | D14: 5500 | E14: Sun Pacific | F14: CLM-Blk2B-ADV-JAN | I14: Block 12 | J14: =SUMIF($C$2:$C$50,I14,$D$2:$D$50) -> 32450 | L14: =J14/K14 -> #DIV/0!
B15: 46070 | C15: Block 15 | D15: 10493.87 | E15: Jireh | F15: SR-Blk15 | I15: Block 13W | J15: =SUMIF($C$2:$C$50,I15,$D$2:$D$50) -> 20550 | L15: =J15/K15 -> #DIV/0!
B16: 46112 | C16: Block 13W | D16: 20550 | E16: Sun Pacific | F16: NAV-Blk13W-ADV-FEB | I16: Block 14 | J16: =SUMIF($C$2:$C$50,I16,$D$2:$D$50) -> 0 | L16: =J16/K16 -> #DIV/0!
... B21: 46129 | C21: Block 2B | D21: 10847.3 | E21: Sun Pacific | F21: CLM-Blk 2B- FINAL- BINS: 428 | I21: Block 19C | J21: =SUMIF($C$2:$C$50,I21,$D$2:$D$50) -> 10350 | L21: =J21/K21 -> #DIV/0!
I22: N/A | J22: =SUMIFS($D$4:$D$40,$C$4:$C$40,I22) -> 0
I24: Equity Adjustment | J24: 0
I25: Total | J25: =SUM(J2:J21) -> 480427.6
I26: Quickbooks Total | J26: 480427.6
I27: Delta | J27: =J26-J25 -> 0 | L27: =J26-J24 -> 480427.6
I29: Est Total | J29: =Revenue!AB186 -> 1481385.6
I30: Est Amount Remaining | J30: =J29-J25 -> 1000958
I34: Gary's Predictions
I35: Lemons | J35: 130-150
I36: Tangos | J36: 200-225
I37: Lates | J37: 150-200
I38: Cara | J38: 150-200
I40: Block | J40: Total Bins | K40: RMA
I41: 2A | J41: 425 | K41: 249 | L41: =K41/J41 -> 0.58588235
I42: 11 | J42: 875 | K42: 864 | L42: =K42/J42 -> 0.98742857
I43: 16 | J43: 470 | K43: 664 | L43: =K43/J43 -> 1.412766
I44: 12 | J44: 791 | K44: 664 | L44: =K44/J44 -> 0.83944374
I45: 8 | J45: 941 | K45: 438 | L45: =K45/J45 -> 0.46546227
I46: 10 | J46: 627 | K46: 438 | L46: =K46/J46 -> 0.69856459
I47: 9 | J47: 748 | K47: 530 | L47: =K47/J47 -> 0.70855615
I48: 19 | J48: 90 | K48: 253 | L48: =K48/J48 -> 2.8111111

Sheet 2025 Checks
B1: Check Date | C1: Block | D1: Amount | E1: Month | F1: Packhouse | G1: Comments | J1: Block | K1: 2025 Total Check Amount | L1: 2025 Bins | M1: 2025 $/Bin | N1: Final/Not Final | O1: Notes
B2: 45688 | C2: Block 1 | D2: 7450 | E2: DEC | F2: Sun Pacific | G2: CLM ADV | J2: Block 1 | K2: =SUMIFS($D$2:$D$54,$C$2:$C$54,J2) -> 45817.36 | L2: 191 | M2: =K2/L2 -> 239.88147 | N2: Final
B3: 45688 | C3: Block 13W | D3: 11600 | E3: DEC | F3: Sun Pacific | G3: NAV ADV | J3: Block 2A | K3: =SUMIFS($D$2:$D$54,$C$2:$C$54,J3) -> 99121.25 | L3: 400 | M3: =K3/L3 -> 247.80312 | N3: Final
B4: 45688 | C4: Block 2B | D4: 10550 | E4: DEC | F4: Sun Pacific | G4: CLM ADV | J4: Block 2B | K4: =SUMIFS($D$2:$D$54,$C$2:$C$54,J4) -> 42238.7 | L4: 177 | M4: =K4/L4 -> 238.63672 | N4: Final
B5: 45663 | C5: Block 12 | D5: 13650 | E5: OCT/NOV | F5: Sun Pacific | G5: LEM ADV | J5: Block 3 | K5: =SUMIFS($D$2:$D$54,$C$2:$C$54,J5) -> 42512.99 | L5: 478.5 | M5: =K5/L5 -> 88.846374 | N5: Final
B6: 45663 | C6: Block 16L | D6: 8700 | E6: OCT/NOV | F6: Sun Pacific | G6: LEM ADV | J6: Block 4 | K6: =SUMIFS($D$2:$D$54,$C$2:$C$54,J6) -> 107428.13 | L6: 538 | M6: =K6/L6 -> 199.68054 | N6: Final
B7: 45663 | C7: Block 1 | D7: 16900 | E7: OCT/NOV | F7: Sun Pacific | G7: CLM ADV | J7: Block 5 | K7: =SUMIFS($D$2:$D$54,$C$2:$C$54,J7) -> 24749.61 | L7: 123 | M7: =K7/L7 -> 201.21634 | N7: Final
B8: 45663 | C8: Block 2B | D8: 11800 | E8: OCT/NOV | F8: Sun Pacific | G8: CLM ADV | J8: Block 6 | K8: =SUMIFS($D$2:$D$54,$C$2:$C$54,J8) -> 36754.73 | L8: 173 | M8: =K8/L8 -> 212.45509 | N8: Final
B9: 45719 | C9: Block 18W | D9: 8500 | E9: JAN | F9: Sun Pacific | G9: NAV ADV | J9: Block 7 | K9: =SUMIFS($D$2:$D$54,$C$2:$C$54,J9) -> 151096.46 | L9: 660 | M9: =K9/L9 -> 228.93403 | N9: Final
B10: 45719 | C10: Block 19C | D10: 1200 | E10: JAN | F10: Sun Pacific | G10: CAR ADV | J10: Block 8 | K10: =SUMIFS($D$2:$D$54,$C$2:$C$54,J10) -> 96764.76 | L10: 390 | M10: =K10/L10 -> 248.11477 | N10: Final
B11: 45719 | C11: Block 9 | D11: 42450 | E11: JAN | F11: Sun Pacific | G11: CAR ADV | J11: Block 9 | K11: =SUMIFS($D$2:$D$54,$C$2:$C$54,J11) -> 158890.93 | L11: 706 | M11: =K11/L11 -> 225.05797 | N11: Final
B12: 45769 | C12: Block 1 | D12: 21467.36 | E12: NOV/DEC | F12: Sun Pacific | G12: Final CLEM | J12: Block 10 | K12: =SUMIFS($D$2:$D$54,$C$2:$C$54,J12) -> 149939.52 | L12: =201+396 -> 597 | M12: =K12/L12 -> 251.15497 | N12: Final | O12: The final packouts are weird- so double check
B13: 45769 | C13: Block 2B | D13: 19888.7 | E13: NOV/DEC | F13: Sun Pacific | G13: Final CLEM | J13: Block 11 | K13: =SUMIFS($D$2:$D$54,$C$2:$C$54,J13) -> 215018.9 | L13: 966 | M13: =K13/L13 -> 222.58685 | N13: Final
B14: 45748 | C14: Block 17 | D14: 15950 | E14: FEB | F14: Sun Pacific | G14: MUR ADV | J14: Block 12 | K14: =SUMIFS($D$2:$D$54,$C$2:$C$54,J14) -> 96921.91 | L14: 825 | M14: =K14/L14 -> 117.4811 | N14: Final
B15: 45748 | C15: Block 2A | D15: 37900 | E15: FEB | F15: Sun Pacific | G15: MUR ADV | J15: Block 13W | K15: =SUMIFS($D$2:$D$54,$C$2:$C$54,J15) -> 20905.02 | L15: 111 | M15: =K15/L15 -> 188.33351 | N15: Final
B16: 45748 | C16: Block 9 | D16: 22350 | E16: FEB | F16: Sun Pacific | G16: CAR ADV | J16: Block 14 | K16: =SUMIFS($D$2:$D$54,$C$2:$C$54,J16) -> 0 | L16: 11.5 | M16: =K16/L16 -> 0 | N16: Final | O16: Grouped with Blk 3
B17: 45755 | C17: N/A | D17: 20384 | E17: N/A | F17: Sun Pacific | G17: NAV EQ Pick Adj | J17: Block 15 | K17: =SUMIFS($D$2:$D$54,$C$2:$C$54,J17) -> 50806.25 | L17: 251 | M17: =K17/L17 -> 202.41534 | N17: Final
B18: 45755 | C18: N/A | D18: 2924.43 | E18: N/A | F18: Sun Pacific | G18: Favorable AR | J18: Block 16L | K18: =SUMIFS($D$2:$D$54,$C$2:$C$54,J18) -> 37030.96 | L18: 370 | M18: =K18/L18 -> 100.08368 | N18: Final
B19: 45777 | C19: Block 11 | D19: 80100 | E19: MAR | F19: Sun Pacific | G19: MUR ADV | J19: Block 17 | K19: =SUMIFS($D$2:$D$54,$C$2:$C$54,J19) -> 37615.47 | L19: 159 | M19: =K19/L19 -> 236.57528 | N19: Final
B20: 45805 | C20: Block 16L | D20: 10650 | E20: APR | F20: Sun Pacific | G20: LEM ADV | J20: Block 18W | K20: =SUMIFS($D$2:$D$54,$C$2:$C$54,J20) -> 16111.26 | L20: 82 | M20: =K20/L20 -> 196.47878 | N20: Final
B21: 45824 | C21: Block 3 | D21: 5614.1 | F21: Jirah | G21: NAVEL BLk 3316003 | J21: Block 19C | K21: =SUMIFS($D$2:$D$54,$C$2:$C$54,J21) -> 3215.26 | L21: 16 | M21: =K21/L21 -> 200.95375 | N21: Final
B22: 45824 | C22: Block 7 | D22: 19745.15 | F22: Jirah | G22: Valencia BLk 3316007 | J22: N/A | K22: =SUMIFS($D$2:$D$40,$C$2:$C$40,J22) -> 23308.43
B23: 45839 | C23: Block 10 | D23: 30800 | E23: MAY | F23: Sun Pacific | G23: NAV ADV
B24: 45839 | C24: Block 11 | D24: 23950 | E24: MAY | F24: Sun Pacific | G24: MUR ADV | J24: Equity Adjustment | K24: 10100
B25: 45839 | C25: Block 17 | D25: 6650 | E25: MAY | F25: Sun Pacific | G25: MUR ADV | J25: Total | K25: =SUM(D2:D54)+K24 -> 1466347.9
B26: 45839 | C26: Block 2A | D26: 21050 | E26: MAY | F26: Sun Pacific | G26: MUR ADV | J26: Quickbooks Total | K26: 1466347.9
B27: 45839 | C27: Block 8 | D27: 55500 | E27: MAY | F27: Sun Pacific | G27: NAV ADV | J27: Delta | K27: =K26-K25 -> 0 | M27: =K26-K24 -> 1456247.9
B28: 45839 | C28: Block 9 | D28: 14650 | E28: MAY | F28: Sun Pacific | G28: CAR ADV
B29: 45839 | C29: Block 12 | D29: 34200 | E29: MAY | F29: Sun Pacific | G29: LEM ADV | J29: Est Total | K29: =Revenue!AB174 -> 1432939.5
B30: 45847 | C30: Block 15 | D30: 8399.26 | F30: Jireh | G30: GRPFRT | J30: Est Amount Remaining | K30: =K29-K25 -> -33408.43
B31: 45847 | C31: Block 3 | D31: 6750.75 | F31: Jireh | G31: NAVEL BLk 3316003
B32: 45847 | C32: Block 4 | D32: 15476.56 | F32: Jireh
B33: 45847 | C33: Block 5 | D33: 3474.81 | F33: Jireh
B34: 45847 | C34: Block 7 | D34: 25924 | F34: Jireh
B35: 45867 | C35: Block 10 | D35: 52800 | E35: JUN | F35: Sun Pacific | G35: NAV ADV
B36: 45867 | C36: Block 11 | D36: 20400 | E36: JUN | F36: Sun Pacific | G36: MUR ADV
B37: 45873 | C37: Block 3 | D37: 30148.14 | F37: Jirah | G37: BLK 3 Wash Navel
B38: 45869 | C38: Block 13W | D38: 9305.02 | E38: DEC | F38: Sun Pacific | G38: FINAL NAV
B39: 45869 | C39: Block 18W | D39: 7611.26 | E39: JAN | F39: Sun Pacific | G39: FINAL NAV
B40: 45907 | C40: Block 11 | D40: 90568.9 | E40: MAR-JUN | F40: Sun Pacific | G40: FINAL MUR
...

Sheet 2024 Checks
B1: Check Date | D1: Block | E1: Amount | F1: Month | G1: Bins | H1: $/bin | I1: Packhouse | J1: Comments | K1: Notes | M1: Block | N1: Total Check Amount | O1: Est Total | P1: Bins | Q1: Est $/Bin | R1: Final/Not Final | S1: Notes
B2: 45310 | C2: =MONTH(B2) -> 1 | D2: Block 12 | E2: 13500 | F2: Oct/Nov | H2: =+E2/G2 -> #DIV/0! | I2: Sun Pacific | J2: LEM ADV 12 OCT/NOV PACKS | K2: where did I get the bins from? | M2: Block 1 | N2: =SUMIFS($E$2:$E$62,$D$2:$D$62,M2) -> 16953.94 | O2: =N2 -> 16953.94 | P2: =SUMIFS($G$2:$G$62,$D$2:$D$62,M2) -> 101 | Q2: =O2/P2 -> 167.86079 | R2: Final | S2: Poor packout because the fruit was oversized and the fruit dried out internally. Cutting back on water next year - per Tim
B3: 45320 | C3: =MONTH(B3) -> 1 | D3: Block 12 | E3: 29000 | F3: Dec | H3: =+E3/G3 -> #DIV/0! | I3: Sun Pacific | J3: LEM ADV 12 DEC PACKS | K3: where did I get the bins from? | M3: Block 2A | N3: =SUMIFS($E$2:$E$62,$D$2:$D$62,M3) -> 99990.21 | O3: =N3 -> 99990.21 | P3: =SUMIFS($G$2:$G$62,$D$2:$D$62,M3) -> 362 | Q3: =O3/P3 -> 276.21605 | R3: Final
B4: 45320 | C4: =MONTH(B4) -> 1 | D4: Block 16L | E4: 4750 | F4: Dec | H4: =+E4/G4 -> #DIV/0! | I4: Sun Pacific | J4: LEM ADV 16W DEC PACKS | M4: Block 2B | N4: =SUMIFS($E$2:$E$62,$D$2:$D$62,M4) -> 58847.76 | O4: =N4 -> 58847.76 | P4: =SUMIFS($G$2:$G$62,$D$2:$D$62,M4) -> 175 | Q4: =O4/P4 -> 336.27291 | R4: Final
B5: 45320 | C5: =MONTH(B5) -> 1 | D5: Block 13W | E5: 7800 | F5: Dec | G5: 64 | H5: =+E5/G5 -> 121.875 | I5: Sun Pacific | J5: NAV ADV 13W DEC PACKS | M5: Block 3 | N5: =SUMIFS($E$2:$E$62,$D$2:$D$62,M5) -> 53708.04 | O5: =N5 -> 53708.04 | P5: =SUMIFS($G$2:$G$62,$D$2:$D$62,M5) -> 471 | Q5: =O5/P5 -> 114.02981 | R5: Final
B6: 45320 | C6: =MONTH(B6) -> 1 | D6: Block 1 | E6: 6150 | F6: Dec | H6: =+E6/G6 -> #DIV/0! | I6: Sun Pacific | J6: CLM ADV 1 DEC PACKS | M6: Block 4 | N6: =SUMIFS($E$2:$E$62,$D$2:$D$62,M6) -> 77097.9 | O6: =N6 -> 77097.9 | P6: =SUMIFS($G$2:$G$62,$D$2:$D$62,M6) -> 444.75 | Q6: =O6/P6 -> 173.3511 | R6: Final
B7: 45320 | C7: =MONTH(B7) -> 1 | D7: Block 2B | E7: 35700 | F7: Dec | H7: =+E7/G7 -> #DIV/0! | I7: Sun Pacific | J7: CLM ADV 2B DEC PACKS | M7: Block 5 | N7: =SUMIFS($E$2:$E$62,$D$2:$D$62,M7) -> 33627.27 | O7: =N7 -> 33627.27 | P7: =SUMIFS($G$2:$G$62,$D$2:$D$62,M7) -> 174 | Q7: =O7/P7 -> 193.26017 | R7: Final
B8: 45320 | C8: =MONTH(B8) -> 1 | D8: Block 9 | E8: 23450 | F8: Dec | H8: =+E8/G8 -> #DIV/0! | I8: Sun Pacific | J8: CAR ADV 9 DEC PACKS | M8: Block 6 | N8: =SUMIFS($E$2:$E$62,$D$2:$D$62,M8) -> 57047.46 | O8: =N8 -> 57047.46 | P8: =SUMIFS($G$2:$G$62,$D$2:$D$62,M8) -> 285.5 | Q8: =O8/P8 -> 199.81597 | R8: Final
B9: 45351 | C9: =MONTH(B9) -> 2 | D9: Block 9 | E9: 4800 | F9: Jan | H9: =+E9/G9 -> #DIV/0! | I9: Sun Pacific | J9: CAR ADV 9 - JAN PACKS | M9: Block 7 | N9: =SUMIFS($E$2:$E$62,$D$2:$D$62,M9) -> 121392.21 | O9: =N9 -> 121392.21 | P9: =SUMIFS($G$2:$G$62,$D$2:$D$62,M9) -> 650 | Q9: =O9/P9 -> 186.75725 | R9: Final
B10: 45414 | C10: =MONTH(B10) -> 5 | D10: Block 2A | E10: 47750 | F10: March | H10: =+E10/G10 -> #DIV/0! | I10: Sun Pacific | J10: MUR ADV 2A - MAR PACKS | M10: Block 8 | N10: =SUMIFS($E$2:$E$62,$D$2:$D$62,M10) -> 59959.64 | O10: =N10 -> 59959.64 | P10: =SUMIFS($G$2:$G$62,$D$2:$D$62,M10) -> 571 | Q10: =O10/P10 -> 105.00813 | R10: Final
B11: 45426 | C11: =MONTH(B11) -> 5 | D11: Block 1 | E11: 10803.94 | F11: Final | G11: 101 | H11: =+E11/G11 -> 106.9697 | I11: Sun Pacific | J11: FINAL CLEM | M11: Block 9 | N11: =SUMIFS($E$2:$E$62,$D$2:$D$62,M11) -> 126287.85 | O11: =N11 -> 126287.85 | P11: =SUMIFS($G$2:$G$62,$D$2:$D$62,M11) -> 668 | Q11: =O11/P11 -> 189.05367 | R11: Final
B12: 45426 | C12: =MONTH(B12) -> 5 | D12: Block 2B | E12: 23147.76 | F12: Final | G12: 175 | H12: =+E12/G12 -> 132.27291 | I12: Sun Pacific | J12: FINAL CLEM | M12: Block 10 | N12: =SUMIFS($E$2:$E$62,$D$2:$D$62,M12) -> 97214.59 | O12: =N12 -> 97214.59 | P12: =SUMIFS($G$2:$G$62,$D$2:$D$62,M12) -> 447 | Q12: =O12/P12 -> 217.4823 | R12: Final
B13: 45442 | C13: =MONTH(B13) -> 5 | D13: Block 11 | E13: 14700 | F13: April | H13: =+E13/G13 -> #DIV/0! | I13: Sun Pacific | J13: MUR ADV 11 - APR PACKS | M13: Block 11 | N13: =SUMIFS($E$2:$E$62,$D$2:$D$62,M13) -> 59801.75 | O13: =N13 -> 59801.75 | P13: =144+160 -> 304 | Q13: =O13/P13 -> 196.71628 | R13: Final
B14: 45442 | C14: =MONTH(B14) -> 5 | D14: Block 10 | E14: 47050 | F14: April | H14: =+E14/G14 -> #DIV/0! | I14: Sun Pacific | J14: NAV AVD 10 - APR PACKS | M14: Block 12 | N14: =SUMIFS($E$2:$E$62,$D$2:$D$62,M14) -> 108339.59 | O14: =N14 -> 108339.59 | P14: =SUMIFS($G$2:$G$62,$D$2:$D$62,M14) -> 1011 | Q14: =O14/P14 -> 107.16082 | R14: Final
B15: 45442 | C15: =MONTH(B15) -> 5 | D15: Block 9 | E15: 12350 | F15: April | H15: =+E15/G15 -> #DIV/0! | I15: Sun Pacific | J15: CAR ADV 9 - ARP PACKS | M15: Block 13W | N15: =SUMIFS($E$2:$E$62,$D$2:$D$62,M15) -> 13113.51 | O15: =N15 -> 13113.51 | P15: =SUMIFS($G$2:$G$62,$D$2:$D$62,M15) -> 64 | Q15: =O15/P15 -> 204.89859 | R15: Final
B16: 45475 | C16: =MONTH(B16) -> 7 | D16: Block 11 | E16: 19000 | F16: May | H16: =+E16/G16 -> #DIV/0! | I16: Sun Pacific | J16: MUR ADV 11 - MAY PACKS | M16: Block 16L | N16: =SUMIFS($E$2:$E$62,$D$2:$D$62,M16) -> 5767.58 | O16: =N16 -> 5767.58 | P16: =SUMIFS($G$2:$G$62,$D$2:$D$62,M16) -> 91 | Q16: =O16/P16 -> 63.38 | R16: Final
B17: 45475 | C17: =MONTH(B17) -> 7 | D17: Block 2A | E17: 11400 | F17: May | H17: =+E17/G17 -> #DIV/0! | I17: Sun Pacific | J17: MUR ADV 2A - MAY PACKS | M17: Block 17 | N17: =SUMIFS($E$2:$E$62,$D$2:$D$62,M17) -> 900 | O17: =N17 -> 900 | P17: =SUMIFS($G$2:$G$62,$D$2:$D$62,M17) -> 5 | Q17: =O17/P17 -> 180 | R17: Final
B18: 45475 | C18: =MONTH(B18) -> 7 | D18: Block 12 | E18: 34350 | F18: May | H18: =+E18/G18 -> #DIV/0! | I18: Sun Pacific | J18: LEM ADV 12 - MAY PACKS
B19: 45475 | C19: =MONTH(B19) -> 7 | D19: Block 9 | E19: 17400 | F19: May | H19: =+E19/G19 -> #DIV/0! | I19: Sun Pacific | J19: CAR ADV 9 - MAY PACKS
B20: 45484 | C20: =MONTH(B20) -> 7 | D20: Block 17 | E20: 900 | F20: Final | G20: 5 | H20: =+E20/G20 -> 180 | I20: McFarlin Family Farms | J20: 5 BINS OF TANGOS | M20: Favorable AR (Sun Pacific) | N20: 10093.6
B21: 45503 | C21: =MONTH(B21) -> 7 | D21: Block 2A | E21: 6300 | F21: Jun | H21: =+E21/G21 -> #DIV/0! | I21: Sun Pacific | J21: MUR ADV 2A - JUN PACKS | M21: 2019 Revolving Fund Dist | N21: 8246.2
B22: 45503 | C22: =MONTH(B22) -> 7 | D22: Block 8 | E22: 16250 | F22: Jun | H22: =+E22/G22 -> #DIV/0! | I22: Sun Pacific | J22: NAV ADV 8 - JUN PACKS
B23: 45516 | C23: =MONTH(B23) -> 8 | D23: Block 13W | E23: 5313.51 | F23: Final | H23: =+E23/G23 -> #DIV/0! | I23: Sun Pacific | J23: FINAL NAV | M23: Total | N23: =SUM(N2:N21) -> 1008389.1
B24: 45538 | C24: =MONTH(B24) -> 9 | D24: Block 9 | E24: 68287.85 | F24: Final | G24: 668 | H24: =+E24/G24 -> 102.22732 | I24: Sun Pacific | J24: FINAL CAR | M24: Quickbooks Total | N24: 1008389.1
B25: 45539 | C25: =MONTH(B25) -> 9 | D25: Block 3 | E25: 53708.04 | F25: Final | G25: 471 | H25: =+E25/G25 -> 114.02981 | I25: Sun Pacific | J25: BLK 3 WASH NAVEL | M25: Delta | N25: =N24-N23 -> 0
B26: 45558 | C26: =MONTH(B26) -> 9 | D26: Block 4 | E26: 35448.73 | F26: Progress | H26: =+E26/G26 -> #DIV/0! | I26: Sun Pacific | J26: POOL J23CV01 BLCK 3316004 PROGRESS PAY
B27: 45558 | C27: =MONTH(B27) -> 9 | D27: Block 5 | E27: 16121.25 | F27: Progress | H27: =+E27/G27 -> #DIV/0! | I27: Sun Pacific | J27: POOL J23CV01 BLCK 3316005 PROGRESS PAY | M27: Est Total | N27: =Revenue!AE155 -> 1008389.1
B28: 45558 | C28: =MONTH(B28) -> 9 | D28: Block 6 | E28: 27625.91 | F28: Progress | H28: =+E28/G28 -> #DIV/0! | I28: Sun Pacific | J28: POOL J23CV01 BLCK 3316006 PROGRESS PAY | M28: Est Amount Remaining | N28: =N27-N24 -> 0
B29: 45558 | C29: =MONTH(B29) -> 9 | D29: Block 7 | E29: 56945.35 | F29: Progress | H29: =+E29/G29 -> #DIV/0! | I29: Sun Pacific | J29: POOL J23CV01 BLCK 3316007 PROGRESS PAY
B30: 45572 | C30: =MONTH(B30) -> 10 | D30: Block 11 | E30: 14269.2 | F30: Final | G30: 160 | H30: =+E30/G30 -> 89.1825 | I30: Sun Pacific | J30: FINAL MUR 24MRL01 | K30: From $27,941.80 invoice
B31: 45572 | C31: =MONTH(B31) -> 10 | D31: Block 2A | E31: 13672.6 | F31: Final | G31: 164 | H31: =+E31/G31 -> 83.369512 | I31: Sun Pacific | J31: FINAL MUR 24MRL02 | K31: From $27,941.80 invoice
B32: 45572 | C32: =MONTH(B32) -> 10 | D32: Block 11 | E32: 11832.55 | F32: Final | G32: 144 | H32: =+E32/G32 -> 82.170486 | I32: Sun Pacific | J32: FINAL MUR 24MUR01 | K32: From $32,700.16 invoice
B33: 45572 | C33: =MONTH(B33) -> 10 | D33: Block 2A | E33: 20867.61 | F33: Final | G33: 198 | H33: =+E33/G33 -> 105.39197 | I33: Sun Pacific | J33: FINAL MUR 24MUR02 | K33: From $32,700.16 invoice
B34: 45583 | C34: =MONTH(B34) -> 10 | D34: Block 8 | E34: 43709.64 | F34: Final | G34: 571 | H34: =+E34/G34 -> 76.549282 | I34: Sun Pacific | J34: FINAL NAV 24GML04
B35: 45595 | C35: =MONTH(B35) -> 10 | D35: Block 10 | E35: 50164.59 | F35: Final | G35: 447 | H35: =+E35/G35 -> 112.22503 | I35: Sun Pacific | J35: FINAL NAV 24LTH06
B36: 45614 | C36: =MONTH(B36) -> 11 | D36: Block 12 | E36: 31489.59 | F36: Final | G36: 1011 | H36: =+E36/G36 -> 31.146973 | I36: Sun Pacific | J36: FINAL LEM 24LEM01 | K36: From $32,507.17 invoice
B37: 45614 | C37: =MONTH(B37) -> 11 | D37: Block 16L | E37: 1017.58 | F37: Final | G37: 91 | H37: =+E37/G37 -> 11.182198 | I37: Sun Pacific | J37: FINAL LEM 24LEM01 | K37: From $32,507.17 invoice
B38: 45618 | C38: =MONTH(B38) -> 11 | D38: Block 4 | E38: 41649.17 | F38: Final | G38: 444.75 | H38: =+E38/G38 -> 93.646251 | I38: Jireh | J38: Blk 4 Valencia
B39: 45618 | C39: =MONTH(B39) -> 11 | D39: Block 5 | E39: 17506.02 | F39: Final | G39: 174 | H39: =+E39/G39 -> 100.60931 | I39: Jireh | J39: Blk 5 Valencia
B40: 45618 | C40: =MONTH(B40) -> 11 | D40: Block 6 | E40: 29421.55 | F40: Final | G40: 285.5 | H40: =+E40/G40 -> 103.05271 | I40: Jireh | J40: Blk 6 Valencia
...

Sheet 2023 Checks
G2: Total | H2: Bins | I2: $/bin | K2: Comments
B3: 44951 | C3: Block 1 | D3: 13700 | E3: Oct/Nov | G3: =D3/0.75 -> 18266.667 | H3: =(528+656)/16 -> 74 | I3: =G3/H3 -> 246.84685
C4: Block 12 | D4: 26350 | E4: Oct/Nov | G4: =D4/0.75 -> 35133.333 | H4: =(176+480+2096)/16 -> 172 | I4: =G4/H4 -> 204.26357 | K4: 75% advance
C5: Block 2B | D5: 23300 | E5: Oct/Nov | G5: =D5/0.75 -> 31066.667 | H5: =(768+992)/16 -> 110 | I5: =G5/H5 -> 282.42424
B7: 44974 | C7: Block 1 | D7: 19500 | E7: Dec | G7: =D7/0.75 -> 26000 | H7: =1552/16 -> 97 | I7: =G7/H7 -> 268.04124
C8: Block 2B | D8: 15100 | E8: Dec | G8: =D8/0.75 -> 20133.333 | H8: =1640/16 -> 102.5 | I8: =G8/H8 -> 196.42276
B10: 44999 | C10: Block 13W | D10: 5100 | E10: Jan | G10: =D10/0.75 -> 6800 | H10: =688/16 -> 43 | I10: =G10/H10 -> 158.13953 | K10: 20% juice
C11: Block 9 | D11: 48550 | E11: Jan | G11: =D11/0.75 -> 64733.333 | H11: =(2400+1600+1392)/16 -> 337 | I11: =G11/H11 -> 192.08704
B13: 45029 | C13: Block 11 | D13: 28400 | E13: Feb | G13: =D13/0.75 -> 37866.667 | H13: =2304/16 -> 144 | I13: =G13/H13 -> 262.96296 | K13: 13% juice
C14: Block 2a | D14: 20600 | E14: Feb | G14: =D14/0.75 -> 27466.667 | H14: =1544/16 -> 96.5 | I14: =G14/H14 -> 284.62867 | K14: 87% was fancy, only 10% juice
B16: 45078 | C16: Block 1 | D16: 14042.32 | E16: Final
C17: Block 2b | D17: 16736.92 | E17: Final
B19: 45092 | C19: Block 11 | D19: 14450 | E19: April | G19: =D19/0.75 -> 19266.667 | H19: =2528/16 -> 158 | I19: =G19/H19 -> 121.94093 | K19: 40% juice
C20: Block 2A | D20: 12250 | E20: April | G20: =D20/0.75 -> 16333.333 | H20: =1388/16 -> 86.75 | I20: =G20/H20 -> 188.2805 | K20: 31% juice, 67% fancy
C21: Block 12 | D21: 36600 | E21: April | G21: =D21/0.65 -> 56307.692 | H21: =(5312+4800+800)/16 -> 682 | I21: =G21/H21 -> 82.562599 | K21: 65% advance // 37% juice
B23: 45120 | C23: Block 9 | D23: 26450 | E23: May | G23: =D23/0.75 -> 35266.667 | H23: =5064/16 -> 316.5 | I23: =G23/H23 -> 111.42707 | K23: 35% juice
B25: 45126 | C25: Block 3 | D25: 21300 | E25: 50% advance | G25: =D25/0.5 -> 42600 | H25: 399 | I25: =G25/H25 -> 106.76692 | K25: 50% advance
B27: 45133 | C27: Block 10 | D27: 58050 | E27: June | G27: =D27/0.75 -> 77400 | H27: =8624/16 -> 539 | I27: =G27/H27 -> 143.59926
C28: Block 8 | D28: 53200 | E28: June | G28: =D28/0.75 -> 70933.333 | H28: =9224/16 -> 576.5 | I28: =G28/H28 -> 123.04134
B30: 45183 | C30: Block 9 | D30: 55017.54 | E30: Final
B32: 45176 | C32: Block 3 | D32: 24471.06 | E32: Final
B34: 45161 | C34: Block 13W | D34: 3264.3 | E34: Final
B36: 45194 | C36: Valencias | D36: 56649.02 | E36: Thru 9/22 | G36: =+D36/0.5 -> 113298.04 | H36: 804 | I36: =+G36/H36 -> 140.91796
B38: 45191 | C38: Block 11 | D38: 22913.05 | E38: Final
B40: 45191 | C40: Block 2a | D40: 15158.11 | E40: Final
B42: 45216 | C42: Block 8 | D42: 41686.01 | E42: Final
B44: 45230 | C44: Block 10 | D44: 60834.61 | E44: Final
B46: 45237 | C46: Block 12 | D46: 57190.18 | E46: Final
C47: Block 16L | D47: 942.27 | E47: Final
B49: 45280 | C49: Block 4 | D49: 74499.28
C50: Block 5 | D50: 14007.6
C51: Block 6 | D51: 23352.6
C52: Block 7 | D52: 265914.86
B54: Equity Adj (Sun Pacific) | D54: 34953
B56: Other | D56: =SUM(D62:D63) -> 9869.89
D59: =SUM(D3:D56) -> 1214402.6
B62: 2022 Equity Adj (Villa Park) | D62: 2465.89
B63: 21-22 Equity Adj (Sun Pacific) | D63: 7404

Sheet 2022 - Checks
F2: Total | G2: Bins | H2: $/bin
B3: 44578 | C3: Block 1 | D3: 11750 | E3: Oct/Nov | F3: =+D3/0.75 -> 15666.667 | G3: =736/16 -> 46 | H3: =+F3/G3 -> 340.57971
B5: 44592 | C5: Block 1 | D5: 8550 | E5: Dec | F5: =+D5/0.75 -> 11400 | G5: =480/16 -> 30 | H5: =+F5/G5 -> 380
C6: Block 2B | D6: 29400 | E6: Dec | F6: =+D6/0.75 -> 39200 | G6: =2160/16 -> 135 | H6: =+F6/G6 -> 290.37037
C7: Block 12 | D7: 66450 | E7: Dec | F7: =+D7/0.75 -> 88600 | G7: =(1600+4400)/16 -> 375 | H7: =+F7/G7 -> 236.26667
D8: =SUM(D5:D7) -> 104400
B10: 44622 | C10: Block 9 | D10: 30150 | E10: Jan | F10: =+D10/0.75 -> 40200 | G10: =3184/16 -> 199 | H10: =+F10/G10 -> 202.01005
C11: Block 13W | D11: 1950 | E11: Jan | F11: =+D11/0.75 -> 2600 | G11: =352/16 -> 22 | H11: =+F11/G11 -> 118.18182
D12: =SUM(D10:D11) -> 32100
B14: 44656 | C14: Block 11 | D14: 35850 | E14: Feb | F14: =+D14/0.75 -> 47800 | G14: =2144/16 -> 134 | H14: =+F14/G14 -> 356.71642
C15: Block 2A | D15: 26350 | E15: Feb | F15: =+D15/0.75 -> 35133.333 | G15: =1568/16 -> 98 | H15: =+F15/G15 -> 358.5034
D16: =SUM(D14:D15) -> 62200
B18: 44684 | C18: Block 9 | D18: 41000 | E18: March | F18: =+D18/0.75 -> 54666.667 | G18: =+(2464+1856)/16 -> 270 | H18: =+F18/G18 -> 202.46914
B20: 44712 | C20: Block 8 | D20: 62550 | E20: April | F20: =+D20/0.75 -> 83400 | G20: =5600/16 -> 350 | H20: =+F20/G20 -> 238.28571
B22: 44697 | C22: Block 1 | D22: 4912.15 | E22: Final
C23: Block 2B | D23: 7572.25 | E23: Final
B25: 44739 | C25: Block 10 | D25: 37000 | E25: May | F25: =+D25/0.75 -> 49333.333 | G25: =4928/16 -> 308 | H25: =+F25/G25 -> 160.17316
C26: Block 12 | D26: 20900 | E26: May | F26: =+D26/0.6 -> 34833.333 | G26: =4800/16 -> 300 | H26: =+F26/G26 -> 116.11111 | J26: 60% advance
C27: Block 8 | D27: 26400 | E27: May | F27: =+D27/0.75 -> 35200 | G27: =(1408+800)/16 -> 138 | H27: =+F27/G27 -> 255.07246
B29: 44748 | C29: Block 3 | D29: 62950.81 | E29: Final
B31: 44769 | C31: Block 9 | D31: 39424.3 | E31: Final
B33: 44767 | C33: Block 12 | D33: 11850 | E33: Jun | F33: =+D33/0.6 -> 19750 | G33: =(280+2400)/16 -> 167.5 | H33: =+F33/G33 -> 117.91045 | J33: 60% advance
C35: Block 4 | D35: 8801.08 | F35: Lori at Villa Park said we should expect $242,000 for our valencias
C36: Block 5 | D36: 10518.39
C37: Block 6 | D37: 16888.83
C38: Block 7 | D38: 56301.79
B40: 44791 | C40: Block 13W | D40: 1318.45 | E40: Final
B42: 44798 | C42: Block 11 | D42: 18127.95 | E42: Final
C43: Block 2A | D43: 13314.52 | E43: Final
B45: 44844 | C45: Block 8 | D45: 12757.58 | E45: Final (138 bins)
B47: 44847 | C47: Block 8 | D47: 60605.28 | E47: Final (350 bins)
C48: Block 10 | D48: 51313.79 | E48: Final (308 bins)
B50: 44904 | C50: Block 12 | D50: 60255.04 | E50: Final (861 bins)
C52: Block 4 | D52: 59780.69 | E52: Final
C53: Block 5 | D53: 15383.05 | E53: Final
C54: Block 6 | D54: 24779.96 | E54: Final
C55: Block 7 | D55: 87178.74 | E55: Final
D57: =SUM(D3,D8,D12,D16,D18,D20,D22:D23,D25:D27,D29,D31,D33,D35:D38,D45,D47:D48,D50,D52:D55,D42:D43,D40) -> 1022334.6
C63: Block 1 | F63: =SUMIFS($D$3:$D$55,$C$3:$C$55,C63) -> 25212.15
C64: Block 2A | F64: =SUMIFS($D$3:$D$55,$C$3:$C$55,C64) -> 39664.52
...

Sheet 2021 - Checks
F2: Total | G2: Bins | H2: $/bin
B3: 44223 | C3: Block 12 | D3: 52700 | E3: Dec packs | F3: =+D3/0.75 -> 70266.667 | G3: 302 | H3: =+F3/G3 -> 232.67108
C4: Block 2b | D4: 15750 | E4: Dec Packs | F4: =+D4/0.75 -> 21000 | G4: 164 | H4: =+F4/G4 -> 128.04878
D5: =SUM(D3:D4) -> 68450
B7: 44253 | C7: Block 12 | D7: 59750 | E7: Jan Packs | F7: =+D7/0.75 -> 79666.667 | G7: 339 | H7: =+F7/G7 -> 235.00492
C8: Block 2b | D8: 3150 | E8: Jan Packs | F8: =+D8/0.75 -> 4200 | G8: 48 | H8: =+F8/G8 -> 87.5
D9: =SUM(D7:D8) -> 62900
B11: 44284 | C11: Block 9 | D11: 21950 | E11: Feb Packs | F11: =+D11/0.75 -> 29266.667 | G11: 100 | H11: =+F11/G11 -> 292.66667
B13: 44305 | C13: Block 11 | D13: 6800 | E13: March Packs | F13: =+D13/0.75 -> 9066.6667 | G13: =624/16 -> 39 | H13: =+F13/G13 -> 232.47863
C14: Block 2A | D14: 8650 | E14: March Packs | F14: =+D14/0.75 -> 11533.333 | G14: =796/16 -> 49.75 | H14: =+F14/G14 -> 231.8258
C15: Block 12 | D15: 40000 | E15: March Packs | F15: =+D15/0.75 -> 53333.333 | G15: =(432+2400+592+1600)/16 -> 314 | H15: =+F15/G15 -> 169.85138
C16: Block 9 | D16: 17950 | E16: March Packs | F16: =+D16/0.75 -> 23933.333 | G16: 100 | H16: =+F16/G16 -> 239.33333
D17: =SUM(D13:D16) -> 73400
B19: 44341 | C19: Block 9 | D19: 21700 | E19: April Packs | F19: =+D19/0.75 -> 28933.333 | G19: =+(1600+1600+800)/16 -> 250 | H19: =+F19/G19 -> 115.73333
C21: Block 2b | D21: 33482.29 | E21: Final Clem
C23: Block 3 | D23: 6240 | E23: Washingtons | G23: 104
B25: 44383 | C25: Block 9 | D25: 500 | E25: May Packs | F25: =D25/0.75 -> 666.66667 | G25: =2592/16 -> 162 | H25: =+F25/G25 -> 4.1152263
B27: 44414 | C27: Block 10 | D27: =4100+23700+21300 -> 49100 | E27: 50% advance per Tamara | F27: =D27/0.5 -> 98200 | G27: =Revenue!R109 -> 544 | H27: =+F27/G27 -> 180.51471
C28: Block 8 | D28: 38150 | E28: 50% advance per Tamara | F28: =D28/0.5 -> 76300 | G28: =Revenue!P109 -> 700 | H28: =+F28/G28 -> 109
D29: =SUM(D27:D28) -> 87250
B31: 44460 | C31: Block 4 | D31: 36775.63 | E31: 50% advance on fruit received thru 9/18
C32: Block 5 | D32: 10103.84 | E32: 50% advance on fruit received thru 9/18
C33: Block 6 | D33: 16546.09 | E33: 50% advance on fruit received thru 9/18
C34: Block 7 | D34: 3424.27 | E34: 50% advance on fruit received thru 9/18
D35: =SUM(D31:D34) -> 66849.83
B37: 44467 | C37: Block 3 | D37: 3942.71 | E37: Final
B39: 44488 | D39: 105363.86 | E39: Final Lemons
D40: 35275.52 | E40: Final Caras
D41: =SUM(D39:D40) -> 140639.38
B43: 44544 | C43: Block 11 | D43: 813.64 | E43: Final Block 11
C44: Block 2A | D44: 1069.08 | E44: Final Block 2A
B46: 44561 | C46: Block 10 | D46: =5836.78+37658.78+29406.76 -> 72902.32
C47: Block 8 | D47: 53984.05
D48: =SUM(D46:D47) -> 126886.37
B50: 44561 | C50: Block 4 | D50: 64937.04
C51: Block 5 | D51: 12892.54
C52: Block 6 | D52: 23115.28
C53: Block 7 | D53: 95251.68
D54: =SUM(D50:D53) -> 196196.54
D56: =+D5+D9+D11+D17+D19+D21+D23+D25+D29+D37+D41+D43+D44+D48+D35+D54 -> 912269.84
...

Sheet 2020 - Checks
F2: Total | G2: Bins | H2: $/bin
B3: 43983 | C3: Block 2A | D3: 2400 | F3: =+D3/0.75 -> 3200 | G3: =164/16 -> 10.25 | H3: =+F3/G3 -> 312.19512
C4: Block 3 | D4: 20600 | F4: =+D4/0.75 -> 27466.667 | G4: =+(3200+1616)/16 -> 301 | H4: =+F4/G4 -> 91.251384
C5: Block 9 | D5: 64750 | F5: =+D5/0.75 -> 86333.333 | G5: =(800+1600+2792)/16 -> 324.5 | H5: =+F5/G5 -> 266.05033
C6: Total | D6: =SUM(D3:D5) -> 87750
B8: 43921 | C8: Block 9 | D8: 33500 | F8: =+D8/0.75 -> 44666.667 | G8: =(3200)/16 -> 200 | H8: =+F8/G8 -> 223.33333
C9: Block 12 | D9: 75100 | F9: =+D9/0.75 -> 100133.33 | G9: =(4608+4488)/16 -> 568.5 | H9: =+F9/G9 -> 176.13603
C10: Block 3 | D10: 16250 | F10: =+D10/0.75 -> 21666.667 | G10: =4624/16 -> 289 | H10: =+F10/G10 -> 74.971165
C11: Total | D11: =SUM(D8:D10) -> 124850
B13: 43892 | C13: Block 9 | D13: 19300 | F13: =+D13/0.75 -> 25733.333 | G13: 100 | H13: =+F13/G13 -> 257.33333
B15: 43864 | C15: Block 2B | D15: 9400 | F15: =+D15/0.75 -> 12533.333 | G15: =(656+148)/16 -> 50.25 | H15: =+F15/G15 -> 249.41957
C16: Block 12 | D16: 41600 | F16: =+D16/0.75 -> 55466.667 | G16: =4800/16 -> 300 | H16: =+F16/G16 -> 184.88889
C17: Total | D17: =SUM(D15:D16) -> 51000
B19: 43986 | C19: Block 2B | D19: 7468.17
B22: 43857 | C22: Block 2B | D22: 14800 | F22: =+D22/0.75 -> 19733.333 | G22: =1056/16 -> 66 | H22: =+F22/G22 -> 298.9899
B24: 44007 | C24: Block 10 | D24: 31200 | F24: =+D24/0.75 -> 41600 | G24: 413 | H24: =+F24/G24 -> 100.72639
C25: Block 8
C26: Pool 4 | D26: 47050 | F26: =+D26/0.75 -> 62733.333 | G26: 239 | H26: =+F26/G26 -> 262.48257
C27: Pool 6 | D27: =13100+17600 -> 30700 | F27: =+D27/0.75 -> 40933.333 | G27: 375 | H27: =+F27/G27 -> 109.15556
C28: Total | D28: =SUM(D24:D27) -> 108950
B30: 44061 | C30: Block 3 | D30: 13900.38 | E30: Final on 2/26/20 packs (289 bins)
B32: 44092 | C32: Block 12 | D32: 94309.93
C33: Block 9 | D33: 44180.24
C34: Block 3 | D34: 9921.25 | E34: for 301 bins
C35: Total | D35: =SUM(D32:D34) -> 148411.42
B37: 44105 | C37: Block 2A | D37: 720.35 | E37: Final
B39: 44110 | C39: Valencias | D39: 85772 | E39: only thru 9/21/20 - they estimate $283,000 for 2,283 bins
B41: 44126 | D41: 56000
B44: 44140 | C44: Block 8 | D44: =16242.03+24702.22 -> 40944.25 | E44: Final packout on 375 bins
C45: Block 10 | D45: 52287.85 | E45: Final packout
D46: =SUM(D44:D45) -> 93232.1
B48: 44131 | C48: Block 8 | D48: 13892.62
B50: 44196 | C50: Block 4 | D50: 56449.88
C51: Block 5 | D51: 18469.71
C52: Block 6 | D52: 34862.25
C53: Block 7 | D53: 66733.71
D54: =SUM(D50:D53) -> 176515.55
C56: Total | D56: =SUM(D6,D11,D13,D17,D19,D22,D28,D30,D35,D37,D39,D46,D48,D41,D54) -> 1002562.6

Sheet 2019 - Checks
H2: Total | I2: Bins | J2: $/bin
B3: 43468 | C3: Block 12 | D3: 82950 | F3: Oct/Nov advance (346.75 bins) | H3: =+D3/0.75 -> 110600 | I3: 346.75 | J3: =+H3/I3 -> 318.96179
B5: 43531 | C5: Block 2b | D5: 30600 | F5: Dec/Jan advance (197 bins) | H5: =+D5/0.75 -> 40800 | I5: 197 | J5: =+H5/I5 -> 207.1066
B7: 43566 | C7: Block 9 | D7: 45300 | F7: Feb advance (160 bins) | H7: =+D7/0.75 -> 60400 | I7: 200 | J7: =+H7/I7 -> 302
B8: 43566 | C8: Block 12 | D8: 46600 | F8: Feb advance (298.5 bins) | H8: =+D8/0.75 -> 62133.333 | I8: 298.55 | J8: =+H8/I8 -> 208.11701
B9: 43566 | C9: Block 3 | D9: 2700 | F9: Feb advance (86 bins) | H9: =+D9/0.75 -> 3600 | I9: 86 | J9: =+H9/I9 -> 41.860465
B11: 43598 | C11: Block 9 | D11: 21850 | F11: March advance (100 bins) | H11: =+D11/0.75 -> 29133.333 | I11: 100 | J11: =+H11/I11 -> 291.33333
B12: 43598 | C12: Block 3 | D12: 2250 | F12: March advance (196 bins) | H12: =+D12/0.75 -> 3000 | I12: 196 | J12: =+H12/I12 -> 15.306122
B13: 43598 | C13: Block 3 | D13: 550 | F13: March advance (171 bins) | H13: =+D13/0.75 -> 733.33333 | I13: 171 | J13: =+H13/I13 -> 4.288499
B15: 43608 | C15: Block 2b | D15: 11712.5 | F15: Final Clem
B17: 43621 | C17: Block 8 | D17: 24400 | F17: April advance (176 bins) | H17: =+D17/0.75 -> 32533.333 | I17: 176 | J17: =+H17/I17 -> 184.84848
B18: 43621 | C18: Block 9 | D18: 36400 | F18: April advance (178 bins) | H18: =+D18/0.75 -> 48533.333 | I18: 178 | J18: =+H18/I18 -> 272.65918
B20: 43651 | C20: Block 10 | D20: 14250 | F20: May advance (403 bins) | H20: =+D20/0.75 -> 19000 | I20: 403 | J20: =+H20/I20 -> 47.146402
B22: 43685 | C22: Block 3 | D22: 2750 | F22: June advance (130 bins) | H22: =+D22/0.75 -> 3666.6667 | I22: 130 | J22: =+H22/I22 -> 28.205128
B24: 43706 | C24: Block 8 | D24: 11850 | F24: July advance (548 bins) | H24: =+D24/0.75 -> 15800 | I24: 548 | J24: =+H24/I24 -> 28.832117
B26: 43720 | C26: Block 9 | D26: 34671.84 | F26: Final Cara Cara
B28: 43733 | C28: Block 3 | D28: 4068.55 | F28: Final
B30: 43734 | C30: Block 12 | D30: 80485.75 | F30: Final Lemons
C31: Block 3 | D31: =18928.49-100.73 -> 18827.76 | F31: Final
B33: 43783 | C33: Block 8 | D33: 9646.32 | F33: Final Block 8 (548 bins)
C34: Block 8 | D34: 17642.83 | F34: Final Block 8 (176 bins)
C35: Block 10 | D35: 10004 | F35: Final Block 10 (403 bins)
C36: Block 3 | D36: -103.3 | F36: Final June (103 bins)

Sheet 2018 - Checks
B4: 43102 | D4: Block 12 | E4: 51750 | F4: Oct/Nov advance (270 bins)
B6: 43132 | D6: Block 2b | E6: 12300 | F6: Clementines advance
B9: 43165 | D9: Block 12 | E9: 50800 | F9: Jan advance (215 bins)
D10: Block 9 | E10: 47850 | F10: Jan advance ([ ] bins)
B12: 43208 | D12: Block 2b | E12: 5686.97 | F12: Clementines (total)
D14: Block 3 | E14: 47000 | F14: 300 bins
D15: Block 3 | E15: 43950
B17: 43224 | D17: Block 12 | E17: 6100 | F17: March advance (35 bins)
B19: 43257 | D19: Block 12 | E19: 29600 | F19: April advance (300 bins)
B21: 43292 | D21: Block 10 | E21: 18450 | F21: May advance (114 bins)
D22: Block 8 | E22: =63850+71550 -> 135400 | F22: May advance (668 bins)
B24: 43295 | D24: Block 9 | E24: 19846.31
D25: Block 9 | E25: -121.65
B27: 43293 | D27: Block 3 | E27: 42712.72 | F27: final for 300 bins
B29: 43312 | D29: Block 12 | E29: 135170.32 | F29: final for all 820 bins
B31: 43343 | D31: Block 3 | E31: 33569.74 | F31: final for 216 bins
B33: 43370 | D33: Block 8 | E33: 40117.11 | F33: final for 350 bins
D34: Block 8 | E34: 40436.55 | F34: final for 318 bins
D35: Block 10 | E35: 10928.02 | F35: final for 114 bins
B37: 43375 | D37: Block 4 | E37: 22314 | F37: 50% advance for valencias picked through 9/21 (1,136 bins)
D38: Block 5 | E38: 0
D39: Block 6 | E39: 6979
D40: Block 7 | E40: 67648
B42: 43465 | D42: Block 4 | E42: 99165.86
D43: Block 5 | E43: 42373.92
D44: Block 6 | E44: 54546.4 | H44: 1616
D45: Block 7 | E45: 127928.5 | H45: 1536
H46: =SUM(H44:H45) -> 3152
H47: =+H46/16 -> 197
B52: Lemons
C53: Implied
B54: Advance | C54: Total | D54: Bins | E54: $/bin
B55: 51750 | C55: =+B55/0.75 -> 69000 | D55: 270 | E55: =+C55/D55 -> 255.55556
B56: 50800 | C56: =+B56/0.75 -> 67733.333 | D56: 215 | E56: =+C56/D56 -> 315.03876
B57: 6100 | C57: =+B57/0.75 -> 8133.3333 | D57: 35 | E57: =+C57/D57 -> 232.38095
B58: 29600 | C58: =+B58/0.75 -> 39466.667 | D58: 300 | E58: =+C58/D58 -> 131.55556
B59: Weighted Avg | E59: =SUMPRODUCT(D55:D58,E55:E58)/SUM(D55:D58) -> 224.79675
B61: Block 3
C62: Implied
B63: Advance | C63: Total | D63: Bins | E63: $/bin
...

Sheet 2017 - Checks
B4: 42857 | C4: Pool 2 | D4: Block 10 | E4: 5900
C5: Pool 1 | D5: Block 3 | E5: 8200 | F5: April packs advance - 100 bins
E6: =SUM(E4:E5) -> 14100
B8: 42888 | C8: Pool 6 | D8: Block 8 | E8: 83050
B10: 42908 | D10: Block 9 | E10: 12708.45
B12: 42917 | C12: Pool 1 | D12: Block 3 | E12: 5018.19
B14: 42914 | C14: Pool 4 | D14: Block 3 | E14: 68250 | F14: May packs advance - 594 bins
B16: 42927 | D16: Lemons | E16: 71645.13
B18: 42968 | C18: Pool 2 | D18: Block 10 | E18: 4958.51
B20: 42998 | C20: Pool 4 | D20: Block 3 | E20: 34310.21
B22: 43006 | D22: Block 4 | E22: 7853
D23: Block 5 | E23: 15468
D24: Block 6 | E24: 20593
D25: Block 7 | E25: 100496
E26: =SUM(E22:E25) -> 144410
B28: 43006 | C28: Pool 6 | D28: Block 8 | E28: 60713.72
B30: 43099 | D30: Block 4 | E30: 151707.73
D31: Block 5 | E31: 22927.2
D32: Block 6 | E32: 34286.87
D33: Block 7 | E33: 139686.61
E34: =SUM(E30:E33) -> 348608.41
B37: Block 1 | C37: =SUMIFS($E$4:$E$53,$D$4:$D$53,B37) -> 0
B38: Block 2 | C38: =SUMIFS($E$4:$E$53,$D$4:$D$53,B38) -> 0
B39: Block 3 | C39: =SUMIFS($E$4:$E$53,$D$4:$D$53,B39) -> 115778.4
B40: Block 4 | C40: =SUMIFS($E$4:$E$53,$D$4:$D$53,B40) -> 159560.73 | F40: =117373.48-C39 -> 1595.08
B41: Block 5 | C41: =SUMIFS($E$4:$E$53,$D$4:$D$53,B41) -> 38395.2 | F41: 117373.48
B42: Block 6 | C42: =SUMIFS($E$4:$E$53,$D$4:$D$53,B42) -> 54879.87 | F42: =F41-E20-E14 -> 14813.27
B43: Block 7 | C43: =SUMIFS($E$4:$E$53,$D$4:$D$53,B43) -> 240182.61
B44: Block 8 | C44: =SUMIFS($E$4:$E$53,$D$4:$D$53,B44) -> 143763.72
B45: Block 9 | C45: =SUMIFS($E$4:$E$53,$D$4:$D$53,B45) -> 12708.45
B46: Block 10 | C46: =SUMIFS($E$4:$E$53,$D$4:$D$53,B46) -> 10858.51
B47: Lemons | C47: =SUMIFS($E$4:$E$53,$D$4:$D$53,B47) -> 71645.13
B48: Total | C48: =SUM(C37:C47) -> 847772.62
C50: 511494.53
C51: -11440
C52: -403.89
C53: -486.43
C54: =SUM(C50:C53) -> 499164.21
C55: =+C54+E34 -> 847772.62
C59: 876728.58
...

Sheet 2016 - Checks
B4: 42471 | C4: Pool 1 | D4: Block 3 | E4: 7700
B6: 42501 | C6: Pool 3 | D6: Block 1 | E6: 7650
C7: Pool 1 | D7: Block 3 | E7: 3800
C8: Pool 2 | D8: Block 1 | E8: 23300
E9: =SUM(E6:E8) -> 34750
B11: 42527 | C11: Pool 3 | D11: Block 3 | E11: 3900
B13: 42550 | C13: Pool 4 | D13: Block 2 | E13: 1000
C14: Pool 4 | D14: Block 3 | E14: 5000
C15: Pool 6 | D15: Block 8 | E15: 7000
E16: =SUM(E13:E15) -> 13000
B18: 42569 | C18: Pool 3 | D18: Lemons | E18: 76700.26
B20: 42573 | C20: Pool 1 | D20: Block 3 | E20: 9566.81
B22: 42579 | D22: Block 9 | E22: 2567.59
B24: 42578 | C24: Pool 5 | D24: Block 2 | E24: 5950
B26: 42600 | C26: Pool 2 | D26: Block 1 | E26: 28290.71
B28: 42599 | C28: Pool 6 | D28: Block 8 | E28: 23700
B30: 42619 | C30: Pool 3 | D30: Block 1 | E30: 9125.29
C31: Pool 3 | D31: Block 3 | E31: 5326.15
E32: =SUM(E30:E31) -> 14451.44
B34: 42649 | C34: Pool 4 | D34: Block 2 | E34: 296.41
C35: Pool 4 | D35: Block 3 | E35: 4660.55
E36: =SUM(E34:E35) -> 4956.96
B38: 42668 | C38: Pool 5 | D38: Block 2 | E38: 2074.36
B40: 42671 | C40: Pool 6 | D40: Block 8 | E40: 26475.38
B42: 42696 | C42: =Revenue!F54 -> 532 | D42: Block 1 | E42: =$E$46*(C42/SUM($C$42:$C$45)) -> 7365.7761
C43: =Revenue!G54 -> 254 | D43: Block 2 | E43: =$E$46*(C43/SUM($C$42:$C$45)) -> 3516.7427
C44: =+Revenue!K54 -> 818 | D44: Block 3 | E44: =$E$46*(C44/SUM($C$42:$C$45)) -> 11325.573 | G44: I don’t think this should be Block 3
C45: =Revenue!P54 -> 762 | D45: Block 8 | E45: =$E$46*(C45/SUM($C$42:$C$45)) -> 10550.228
E46: 32758.32
B48: 42734 | D48: Block 4 | E48: 90685.64
D49: Block 5 | E49: 25937.71
D50: Block 6 | E50: 44203.73
D51: Block 7 | E51: 102618
E52: =SUM(E48:E51) -> 263445.08
B54: Block 1 | C54: =SUMIFS($E$4:$E$51,$D$4:$D$51,B54) -> 75731.776
B55: Block 2 | C55: =SUMIFS($E$4:$E$51,$D$4:$D$51,B55) -> 12837.513
B56: Block 3 | C56: =SUMIFS($E$4:$E$51,$D$4:$D$51,B56) -> 51279.083 | E56: 39953.51 | F56: =C56-E56 -> 11325.573
B57: Block 4 | C57: =SUMIFS($E$4:$E$51,$D$4:$D$51,B57) -> 90685.64
B58: Block 5 | C58: =SUMIFS($E$4:$E$51,$D$4:$D$51,B58) -> 25937.71
B59: Block 6 | C59: =SUMIFS($E$4:$E$51,$D$4:$D$51,B59) -> 44203.73
...

Sheet 2015 - Checks
B2: 42128 | C2: Pool 2 | D2: Block 1 | E2: 17750
C3: Pool 2 | D3: Block 2 | E3: 3300
C4: Pool 3 | D4: Block 2 | E4: 6650
C5: Pool 3 | D5: Block 3 | E5: 32350
E6: =SUM(E2:E5) -> 60050
B8: 42157 | C8: Pool 6 | D8: Block 8 | E8: 76800
B10: 42174 | D10: Block 12 | E10: 5218.05
B12: 42247 | C12: Pool 2 | D12: Block 1 | E12: 24461.71
C13: Pool 2 | D13: Block 2 | E13: 5063.74
E14: =SUM(E12:E13) -> 29525.45
B16: 42248 | C16: Pool 3 | D16: Block 2 | E16: 9244.7
D17: Block 3 | E17: 36012.39
E18: =SUM(E16:E17) -> 45257.09
B20: 42268 | D20: Block 5 | E20: 4543
D21: Block 6 | E21: 9340
D22: Block 7 | E22: 38497
E23: =SUM(E20:E22) -> 52380
B25: 42268 | D25: Block 8 | E25: 58058.91
B27: 42369 | D27: Block 4 | E27: 83261.6
D28: Block 5 | E28: 8132.93
D29: Block 6 | E29: 17705.7
D30: Block 7 | E30: 67922.83
E31: =SUM(E27:E30) -> 177023.06

Sheet 2014 - Checks
B3: 41739 | C3: Block 3 | D3: Pool 1 | E3: 28850 | G3: Feb Packout
C4: Block 3 | D4: Pool 2 | E4: 27850 | G4: Feb Packout | K4: Block 1 | L4: =SUM(E8,E15,E26,E35) -> 77868.45 | M4: =#REF! -> #REF! | N4: =+L4/M4 -> #REF!
E5: =SUM(E3:E4) -> 56700 | K5: Block 2 | L5: =SUM(E9,E16,E24,E36,) -> 44713.02 | M5: =#REF! -> #REF! | N5: =+L5/M5 -> #REF!
L6: =SUM(L4:L5) -> 122581.47
B7: 41764 | C7: Block 3 | D7: Pool 2 | E7: 19450 | G7: March Packout
C8: Block 1 | D8: Pool 2 | E8: 41450 | G8: March Packout
C9: Block 2 | D9: Pool 2 | E9: 2750 | G9: March Packout
C10: Block 3 | D10: Pool 2 | E10: 7850 | G10: March Packout
E11: =SUM(E7:E10) -> 71500
B13: 41792 | C13: Block 8 | D13: Pool 6 | E13: 86850 | G13: April Packout | I13: =+E13/0.75 -> 115800
I14: =+I13-E13 -> 28950
B15: 41820 | C15: Block 1 | D15: Pool 4 | E15: 7600 | G15: May Packout | I15: 37679.93
C16: Block 2 | D16: Pool 4 | E16: 27800 | G16: May Packout | I16: =+I15-I14 -> 8729.93
E17: =SUM(E15:E16) -> 35400
B19: 41842 | C19: Block 3 | D19: Pool 1 | E19: 19085.54 | G19: Closing out Pool 1
C20: Block 3 | D20: Korea Protocol | E20: 3788.65
C21: All Blocks | D21: Picking Bonus Charge | E21: -312.85
E22: =SUM(E19:E21) -> 22561.34
B24: 41873 | C24: Block 2 | D24: Pool 2 | E24: 1163.48
C25: Block 3 | D25: Pool 2 | E25: 5020.01
C26: Block 1 | D26: Pool 2 | E26: 25738.87
C27: Block 3 | D27: Pool 2 | E27: 33769.52
E28: =SUM(E24:E27) -> 65691.88
B30: 41906 | C30: Block 4 | E30: 54816
C31: Block 5 | E31: 13426
C32: Block 7 | E32: 39135
E33: =SUM(E30:E32) -> 107377
B35: 41926 | C35: Block 1 | D35: Pool 4 | E35: 3079.58
C36: Block 2 | D36: Pool 4 | E36: 12999.54
E37: =SUM(E35:E36) -> 16079.12
B39: 41947 | C39: Block 8 | D39: Pool 6 | E39: 37679.93
B41: 41997 | C41: Block 4 | E41: 65814.57
C42: Block 5 | E42: 23210.41
C43: Block 6 | E43: 45440.72
C44: Block 7 | E44: 51195.81
E45: =SUM(E41:E44) -> 185661.51

Sheet 2013 - Checks
B3: 41397 | C3: Block 1 | D3: Pool 2 | E3: 10050
C4: Block 1 | D4: Pool 3 | E4: 5950
C5: Block 2 | D5: Pool 3 | E5: 7700
C6: Block 3 | D6: Pool 3 | E6: 15300
C7: Block 3 | D7: Pool 4 | E7: 2800
E8: =SUM(E3:E7) -> 41800
B10: 41422 | C10: Block 1 | D10: Pool 3 | E10: 3250
C11: Block 1 | D11: Pool 2 | E11: 5050
C12: Block 2 | D12: Pool 3 | E12: 4200
C13: Block 3 | D13: Pool 3 | E13: 8350
E14: =SUM(E10:E13) -> 20850
B16: 41479 | C16: Block 8 | D16: Pool 6 | E16: 36100
E17: =SUM(E16) -> 36100
B19: 41513 | C19: Block 1 | D19: Pool 2 | E19: 11533.59
E20: =SUM(E19) -> 11533.59
B22: 41530 | C22: Block 1 | D22: Pool 2 | E22: 5283.82
C23: Block 2 | D23: Pool 2 | E23: 6502.93
C24: Block 3 | D24: Pool 2 | E24: 18005.1
E25: =SUM(E22:E24) -> 29791.85
B27: 41536 | C27: Block 3 | D27: Pool 4 | E27: 4331.15
E28: =SUM(E27) -> 4331.15
B30: 41561 | C30: Block 8 | D30: Pool 6 | E30: 39615.48
E31: =SUM(E30) -> 39615.48
B33: 41639 | C33: Block 4 | E33: 31283.85
C34: Block 5 | E34: 11433.99
C35: Block 6 | E35: 15569.42
C36: Block 7 | E36: 58265.93
E37: =SUM(E33:E36) -> 116553.19
B39: 41534 | C39: Block 4 | E39: 22477
C40: Block 5 | E40: 8221
C41: Block 6 | E41: 10836
C42: Block 7 | E42: 41065
C43: Misc | E43: 383.67
E44: =SUM(E39:E43) -> 82982.67
C46: Olives | E46: 48069.6
